<?xml version="1.0" ?>
<robot name="marker" xmlns:xacro="http://ros.org/wiki/xacro">
  <xacro:include filename="$(find marker_description)/urdf/gazebo_properties.xacro"/>
  <xacro:include filename="$(find marker_description)/urdf/trolley.macros.xacro"/>
  <xacro:property name="M_PI" value="3.1415926535897931"/>


  <xacro:property name="wheelWidth" value="0.04"/>
  <xacro:property name="wheelRadius" value="0.0625"/>
  <xacro:property name="wheelMass" value="0.3"/>

  <link name="base_link"/>



  <joint name="marker_base_joint" type="fixed">
    <parent link="base_link"/>
    <child link="marker_link1"/>
    <origin xyz="0 0 0.00630" rpy="0 0 0"/>
    <!--limit effort="30" velocity="1.0" lower="0" upper="0" /-->
  </joint>

  <link name="marker_link1">
    <visual>
      <origin xyz="0 0 0" rpy="0 0 0"/>
      <geometry>
        <mesh filename="package://marker_description/meshes/Trolley_latest.STL" scale="0.001 0.001 0.001"/>
      </geometry>
      <material name="black"/>
    </visual>
    <collision>
      <origin xyz="0 0 0" rpy="0 0 0"/>
      <geometry>
	<!--box size="1.450 1.130 1.936"/-->
        <mesh filename="package://marker_description/meshes/Trolley_latest.STL" scale="0.001 0.001 0.001"/>
      </geometry>
    </collision>
     <inertial>
      <origin xyz="0.61 0.69 1.101"  rpy="0 0 0"/>
      <mass value="17.36"/>
      <!--inertia ixx="1.1175580e-05" ixy="-4.2369783e-11" ixz="-5.9381719e-09" iyy="1.1192413e-05" iyz="-1.4400107e-11" izz="2.0712558e-05"/-->
      <!--box_inertia m="10" x="1.450" y="1.130" z="1.936"/-->
      <inertia ixx="8.2883" ixy="0" ixz="0"
               iyy="7.1187" iyz="0"
               izz="4.7874" />
      </inertial>
  </link>


  <!--wheel_front lr="left" tY="-0.03"/>
  <wheel_front lr="right" tY="1.250"/>
  <wheel_back lr="left" tY="-0.03" />
  <wheel_back lr="right" tY="1.250"/-->


  <joint name="left_wheel_front_joint" type="continuous">
    <parent link="marker_link1"/>
    <child link="left_front_wheel"/>
    <origin xyz="1.13 0.20 0.033" rpy="1.57 0 1.57"/>
    <dynamic damping ="50" friction="0.2"/>
    <axis xyz="0 0 1"/>
  </joint>

  <link name="left_front_wheel">
    <visual>
      <origin xyz="0 0 0" rpy="0 0 0"/>
      <geometry>
        <cylinder length="0.04" radius="${wheelRadius}"/>
      </geometry>
      <material name="black"/>
    </visual>

    <collision>
      <origin xyz="0 0 0" rpy="0 0 0"/>
      <geometry>
        <cylinder length="0.04" radius="${wheelRadius}"/>
      </geometry>
    </collision>
    <inertial>
	<origin xyz="0 0 0.0" />
	<mass value="0.630" />
	<inertia ixx="0.0007411" ixy="0.0" ixz="0.0"
		iyy="0.0007411" iyz="0.0"
		izz="0.00123046875" />
        </inertial>
  </link>

	 <gazebo reference="left_front_wheel">
	    <mu1>10.0</mu1>
	    <mu2>10.0</mu2>
	    <kp>500000.0</kp>
	    <kd>10.0</kd>
	    <maxVel>1.1</maxVel>
	    <material>Gazebo/Black</material>
        </gazebo>

  <joint name="right_wheel_front_joint" type="continuous">
    <parent link="marker_link1"/>
    <child link="right_front_wheel"/>
    <origin xyz="1.145 1.165 0.033" rpy="1.57 0 1.57"/>
    <dynamic damping ="50" friction="0.2"/>
    <axis xyz="0 0 1"/>
  </joint>

  <link name="right_front_wheel">
    <visual>
      <origin xyz="0 0 0" rpy="0 0 0"/>
      <geometry>
        <cylinder length="0.04" radius="${wheelRadius}"/>
      </geometry>
      <material name="black"/>
    </visual>

    <collision>
      <origin xyz="0 0 0" rpy="0 0 0"/>
      <geometry>
        <cylinder length="0.04" radius="${wheelRadius}"/>
      </geometry>
    </collision>
    <inertial>
	<origin xyz="0 0 0.0" />
	<mass value="0.630" />
	<inertia ixx="0.0007411" ixy="0.0" ixz="0.0"
		iyy="0.0007411" iyz="0.0"
		izz="0.00123046875" />
        </inertial>
  </link>

	 <gazebo reference="right_front_wheel">
	    <mu1>10.0</mu1>
	    <mu2>10.0</mu2>
	    <kp>500000.0</kp>
	    <kd>10.0</kd>
	    <maxVel>1.1</maxVel>
	    <material>Gazebo/Black</material>
        </gazebo>


  <joint name="right_wheel_back_joint" type="continuous">
    <parent link="marker_link1"/>
    <child link="right_back_wheel"/>
    <origin xyz="0.029 1.2341 0.033" rpy="1.57 0 1.57"/>
    <dynamic damping ="50" friction="0.2"/>
    <axis xyz="0 0 1"/>
  </joint>

  <link name="right_back_wheel">
    <visual>
      <origin xyz="0 0 0" rpy="0 0 0"/>
      <geometry>
        <cylinder length="0.04" radius="${wheelRadius}"/>
      </geometry>
      <material name="black"/>
    </visual>

    <collision>
      <origin xyz="0 0 0" rpy="0 0 0"/>
      <geometry>
        <cylinder length="0.04" radius="${wheelRadius}"/>
      </geometry>
    </collision>
    <inertial>
	<origin xyz="0 0 0.0" />
	<mass value="0.630" />
	<inertia ixx="0.0007411" ixy="0.0" ixz="0.0"
		iyy="0.0007411" iyz="0.0"
		izz="0.00123046875" />
        </inertial>
  </link>

	 <gazebo reference="right_back_wheel">
	    <mu1>10.0</mu1>
	    <mu2>10.0</mu2>
	    <kp>500000.0</kp>
	    <kd>10.0</kd>
	    <maxVel>1.1</maxVel>
	    <material>Gazebo/Black</material>
        </gazebo>


   <joint name="left_wheel_back_joint" type="continuous">
    <parent link="marker_link1"/>
    <child link="left_back_wheel"/>
    <origin xyz="0.02881 0.172820 0.033" rpy="1.57 0 1.57"/>
    <dynamic damping ="50" friction="0.2"/>
    <axis xyz="0 0 1"/>
  </joint>

  <link name="left_back_wheel">
    <visual>
      <origin xyz="0 0 0" rpy="0 0 0"/>
      <geometry>
        <cylinder length="0.04" radius="${wheelRadius}"/>
      </geometry>
      <material name="black"/>
    </visual>

    <collision>
      <origin xyz="0 0 0" rpy="0 0 0"/>
      <geometry>
        <cylinder length="0.04" radius="${wheelRadius}"/>
      </geometry>
    </collision>
    <inertial>
	<origin xyz="0 0 0.0" />
	<mass value="0.630" />
	<inertia ixx="0.0007411" ixy="0.0" ixz="0.0"
		iyy="0.0007411" iyz="0.0"
		izz="0.00123046875" />
        </inertial>
  </link>

	 <gazebo reference="left_back_wheel">
	    <mu1>10.0</mu1>
	    <mu2>10.0</mu2>
	    <kp>500000.0</kp>
	    <kd>10.0</kd>
	    <maxVel>1.1</maxVel>
	    <material>Gazebo/Black</material>
        </gazebo>



 

  <gazebo reference="marker_link1">
    <material>Gazebo/Red</material>
  </gazebo>
  
  <!--gazebo>
      <plugin name="gazebo_ros_vacuum_gripper" filename="libgazebo_ros_vacuum_gripper.so">
        <robotNamespace>/trolley</robotNamespace>
        <bodyName>base_link</bodyName>
        <topicName>grasping</topicName>
      </plugin>
    </gazebo-->


</robot>
